
DEBUG:root:got to submitProjectEval!!
DEBUG:root:form is valid
ERROR:django.request:Internal Server Error: /project_eval_form/submitted
Traceback (most recent call last):
  File "C:\Python37\lib\site-packages\django\core\handlers\exception.py", line 34, in inner
    response = get_response(request)
  File "C:\Python37\lib\site-packages\django\core\handlers\base.py", line 115, in _get_response
    response = self.process_exception_by_middleware(e, request)
  File "C:\Python37\lib\site-packages\django\core\handlers\base.py", line 113, in _get_response
    response = wrapped_callback(request, *callback_args, **callback_kwargs)
  File "E:\Documents\GitHub\Senior-Design-Scoring-System\Django\scoringsystem\scoringsystem\views.py", line 19, in submitProjectEvalView
    return submitProjectEval(request)
  File "C:\Python37\lib\site-packages\django\views\decorators\csrf.py", line 54, in wrapped_view
    return view_func(*args, **kwargs)
  File "E:\Documents\GitHub\Senior-Design-Scoring-System\Django\scoringsystem\scoringsystem\views.py", line 105, in submitProjectEval
    score.save()
  File "C:\Python37\lib\site-packages\django\db\models\base.py", line 741, in save
    force_update=force_update, update_fields=update_fields)
  File "C:\Python37\lib\site-packages\django\db\models\base.py", line 779, in save_base
    force_update, using, update_fields,
  File "C:\Python37\lib\site-packages\django\db\models\base.py", line 851, in _save_table
    forced_update)
  File "C:\Python37\lib\site-packages\django\db\models\base.py", line 880, in _do_update
    filtered = base_qs.filter(pk=pk_val)
  File "C:\Python37\lib\site-packages\django\db\models\query.py", line 892, in filter
    return self._filter_or_exclude(False, *args, **kwargs)
  File "C:\Python37\lib\site-packages\django\db\models\query.py", line 910, in _filter_or_exclude
    clone.query.add_q(Q(*args, **kwargs))
  File "C:\Python37\lib\site-packages\django\db\models\sql\query.py", line 1290, in add_q
    clause, _ = self._add_q(q_object, self.used_aliases)
  File "C:\Python37\lib\site-packages\django\db\models\sql\query.py", line 1318, in _add_q
    split_subq=split_subq, simple_col=simple_col,
  File "C:\Python37\lib\site-packages\django\db\models\sql\query.py", line 1251, in build_filter
    condition = self.build_lookup(lookups, col, value)
  File "C:\Python37\lib\site-packages\django\db\models\sql\query.py", line 1116, in build_lookup
    lookup = lookup_class(lhs, rhs)
  File "C:\Python37\lib\site-packages\django\db\models\lookups.py", line 20, in __init__
    self.rhs = self.get_prep_lookup()
  File "C:\Python37\lib\site-packages\django\db\models\lookups.py", line 70, in get_prep_lookup
    return self.lhs.output_field.get_prep_value(self.rhs)
  File "C:\Python37\lib\site-packages\django\db\models\fields\__init__.py", line 1821, in get_prep_value
    return int(value)
ValueError: invalid literal for int() with base 10: 'id'
WARNING:django.request:Not Found: /project_eval_form/events.js
DEBUG:root:got to submitProjectEval!!
DEBUG:root:form is valid
ERROR:django.request:Internal Server Error: /project_eval_form/submitted
Traceback (most recent call last):
  File "C:\Python37\lib\site-packages\django\core\handlers\exception.py", line 34, in inner
    response = get_response(request)
  File "C:\Python37\lib\site-packages\django\core\handlers\base.py", line 115, in _get_response
    response = self.process_exception_by_middleware(e, request)
  File "C:\Python37\lib\site-packages\django\core\handlers\base.py", line 113, in _get_response
    response = wrapped_callback(request, *callback_args, **callback_kwargs)
  File "E:\Documents\GitHub\Senior-Design-Scoring-System\Django\scoringsystem\scoringsystem\views.py", line 19, in submitProjectEvalView
    return submitProjectEval(request)
  File "C:\Python37\lib\site-packages\django\views\decorators\csrf.py", line 54, in wrapped_view
    return view_func(*args, **kwargs)
  File "E:\Documents\GitHub\Senior-Design-Scoring-System\Django\scoringsystem\scoringsystem\views.py", line 105, in submitProjectEval
    score.save()
  File "C:\Python37\lib\site-packages\django\db\models\base.py", line 741, in save
    force_update=force_update, update_fields=update_fields)
  File "C:\Python37\lib\site-packages\django\db\models\base.py", line 779, in save_base
    force_update, using, update_fields,
  File "C:\Python37\lib\site-packages\django\db\models\base.py", line 851, in _save_table
    forced_update)
  File "C:\Python37\lib\site-packages\django\db\models\base.py", line 880, in _do_update
    filtered = base_qs.filter(pk=pk_val)
  File "C:\Python37\lib\site-packages\django\db\models\query.py", line 892, in filter
    return self._filter_or_exclude(False, *args, **kwargs)
  File "C:\Python37\lib\site-packages\django\db\models\query.py", line 910, in _filter_or_exclude
    clone.query.add_q(Q(*args, **kwargs))
  File "C:\Python37\lib\site-packages\django\db\models\sql\query.py", line 1290, in add_q
    clause, _ = self._add_q(q_object, self.used_aliases)
  File "C:\Python37\lib\site-packages\django\db\models\sql\query.py", line 1318, in _add_q
    split_subq=split_subq, simple_col=simple_col,
  File "C:\Python37\lib\site-packages\django\db\models\sql\query.py", line 1251, in build_filter
    condition = self.build_lookup(lookups, col, value)
  File "C:\Python37\lib\site-packages\django\db\models\sql\query.py", line 1116, in build_lookup
    lookup = lookup_class(lhs, rhs)
  File "C:\Python37\lib\site-packages\django\db\models\lookups.py", line 20, in __init__
    self.rhs = self.get_prep_lookup()
  File "C:\Python37\lib\site-packages\django\db\models\lookups.py", line 70, in get_prep_lookup
    return self.lhs.output_field.get_prep_value(self.rhs)
  File "C:\Python37\lib\site-packages\django\db\models\fields\__init__.py", line 1821, in get_prep_value
    return int(value)
ValueError: invalid literal for int() with base 10: 'id'
DEBUG:root:got to submitProjectEval!!
DEBUG:root:form is valid
ERROR:django.request:Internal Server Error: /project_eval_form/submitted
Traceback (most recent call last):
  File "C:\Python37\lib\site-packages\django\db\backends\utils.py", line 84, in _execute
    return self.cursor.execute(sql, params)
psycopg2.errors.UndefinedTable: relation "scoringsystem_projecteval" does not exist
LINE 1: UPDATE "scoringsystem_projecteval" SET "judge_email" = 'emai...
               ^


The above exception was the direct cause of the following exception:

Traceback (most recent call last):
  File "C:\Python37\lib\site-packages\django\core\handlers\exception.py", line 34, in inner
    response = get_response(request)
  File "C:\Python37\lib\site-packages\django\core\handlers\base.py", line 115, in _get_response
    response = self.process_exception_by_middleware(e, request)
  File "C:\Python37\lib\site-packages\django\core\handlers\base.py", line 113, in _get_response
    response = wrapped_callback(request, *callback_args, **callback_kwargs)
  File "E:\Documents\GitHub\Senior-Design-Scoring-System\Django\scoringsystem\scoringsystem\views.py", line 19, in submitProjectEvalView
    return submitProjectEval(request)
  File "C:\Python37\lib\site-packages\django\views\decorators\csrf.py", line 54, in wrapped_view
    return view_func(*args, **kwargs)
  File "E:\Documents\GitHub\Senior-Design-Scoring-System\Django\scoringsystem\scoringsystem\views.py", line 105, in submitProjectEval
    score.save()
  File "C:\Python37\lib\site-packages\django\db\models\base.py", line 741, in save
    force_update=force_update, update_fields=update_fields)
  File "C:\Python37\lib\site-packages\django\db\models\base.py", line 779, in save_base
    force_update, using, update_fields,
  File "C:\Python37\lib\site-packages\django\db\models\base.py", line 851, in _save_table
    forced_update)
  File "C:\Python37\lib\site-packages\django\db\models\base.py", line 900, in _do_update
    return filtered._update(values) > 0
  File "C:\Python37\lib\site-packages\django\db\models\query.py", line 760, in _update
    return query.get_compiler(self.db).execute_sql(CURSOR)
  File "C:\Python37\lib\site-packages\django\db\models\sql\compiler.py", line 1429, in execute_sql
    cursor = super().execute_sql(result_type)
  File "C:\Python37\lib\site-packages\django\db\models\sql\compiler.py", line 1100, in execute_sql
    cursor.execute(sql, params)
  File "C:\Python37\lib\site-packages\django\db\backends\utils.py", line 99, in execute
    return super().execute(sql, params)
  File "C:\Python37\lib\site-packages\django\db\backends\utils.py", line 67, in execute
    return self._execute_with_wrappers(sql, params, many=False, executor=self._execute)
  File "C:\Python37\lib\site-packages\django\db\backends\utils.py", line 76, in _execute_with_wrappers
    return executor(sql, params, many, context)
  File "C:\Python37\lib\site-packages\django\db\backends\utils.py", line 84, in _execute
    return self.cursor.execute(sql, params)
  File "C:\Python37\lib\site-packages\django\db\utils.py", line 89, in __exit__
    raise dj_exc_value.with_traceback(traceback) from exc_value
  File "C:\Python37\lib\site-packages\django\db\backends\utils.py", line 84, in _execute
    return self.cursor.execute(sql, params)
django.db.utils.ProgrammingError: relation "scoringsystem_projecteval" does not exist
LINE 1: UPDATE "scoringsystem_projecteval" SET "judge_email" = 'emai...
               ^

WARNING:django.request:Not Found: /judge_eval_form
WARNING:django.request:Not Found: /judge_eval_form/
WARNING:django.request:Not Found: /projects_eval_form/
WARNING:django.request:Not Found: /js/functions.js
WARNING:django.request:Not Found: /project_eval_form/events.js
WARNING:django.request:Not Found: /project_eval_form/events.js
WARNING:django.request:Not Found: /js/functions.js
WARNING:django.request:Not Found: /project_eval_form/events.js
WARNING:django.request:Not Found: /project_eval_form/events.js
WARNING:django.request:Not Found: /js/functions.js
WARNING:django.request:Not Found: /project_eval_form/events.js
WARNING:django.request:Not Found: /js/functions.js
WARNING:django.request:Not Found: /project_eval_form/events.js
WARNING:django.request:Not Found: /js/functions.js
WARNING:django.request:Not Found: /project_eval_form/events.js
WARNING:django.request:Not Found: /project_eval_form/events.js
WARNING:django.request:Not Found: /js/functions.js
WARNING:django.request:Not Found: /project_eval_form/events.js
WARNING:django.request:Not Found: /js/functions.js
WARNING:django.request:Not Found: /project_eval_form/events.js
WARNING:django.request:Not Found: /js/functions.js
WARNING:django.request:Not Found: /project_eval_form/events.js
WARNING:django.request:Not Found: /js/functions.js
WARNING:django.request:Not Found: /project_eval_form/events.js
WARNING:django.request:Not Found: /js/functions.js
WARNING:django.request:Not Found: /project_eval_form/events.js
WARNING:django.request:Not Found: /judge-eval-form/
WARNING:django.request:Not Found: /judge-exp-eval-form/
WARNING:django.request:Not Found: /js/functions.js
WARNING:django.request:Not Found: /project_eval_form/events.js
WARNING:django.request:Not Found: /js/functions.js
WARNING:django.request:Not Found: /project_eval_form/events.js
WARNING:django.request:Not Found: /js/functions.js
WARNING:django.request:Not Found: /project_eval_form/events.js
WARNING:django.request:Not Found: /js/functions.js
WARNING:django.request:Not Found: /project_eval_form/events.js
WARNING:django.request:Not Found: /js/functions.js
WARNING:django.request:Not Found: /project_eval_form/events.js
WARNING:django.request:Not Found: /js/functions.js
WARNING:django.request:Not Found: /project_eval_form/events.js
