
DEBUG:root:got to submitProjectEval!!
DEBUG:root:form is valid
ERROR:django.request:Internal Server Error: /project_eval_form/submitted
Traceback (most recent call last):
  File "C:\Python37\lib\site-packages\django\core\handlers\exception.py", line 34, in inner
    response = get_response(request)
  File "C:\Python37\lib\site-packages\django\core\handlers\base.py", line 115, in _get_response
    response = self.process_exception_by_middleware(e, request)
  File "C:\Python37\lib\site-packages\django\core\handlers\base.py", line 113, in _get_response
    response = wrapped_callback(request, *callback_args, **callback_kwargs)
  File "E:\Documents\GitHub\Senior-Design-Scoring-System\Django\scoringsystem\scoringsystem\views.py", line 19, in submitProjectEvalView
    return submitProjectEval(request)
  File "C:\Python37\lib\site-packages\django\views\decorators\csrf.py", line 54, in wrapped_view
    return view_func(*args, **kwargs)
  File "E:\Documents\GitHub\Senior-Design-Scoring-System\Django\scoringsystem\scoringsystem\views.py", line 105, in submitProjectEval
    score.save()
  File "C:\Python37\lib\site-packages\django\db\models\base.py", line 741, in save
    force_update=force_update, update_fields=update_fields)
  File "C:\Python37\lib\site-packages\django\db\models\base.py", line 779, in save_base
    force_update, using, update_fields,
  File "C:\Python37\lib\site-packages\django\db\models\base.py", line 851, in _save_table
    forced_update)
  File "C:\Python37\lib\site-packages\django\db\models\base.py", line 880, in _do_update
    filtered = base_qs.filter(pk=pk_val)
  File "C:\Python37\lib\site-packages\django\db\models\query.py", line 892, in filter
    return self._filter_or_exclude(False, *args, **kwargs)
  File "C:\Python37\lib\site-packages\django\db\models\query.py", line 910, in _filter_or_exclude
    clone.query.add_q(Q(*args, **kwargs))
  File "C:\Python37\lib\site-packages\django\db\models\sql\query.py", line 1290, in add_q
    clause, _ = self._add_q(q_object, self.used_aliases)
  File "C:\Python37\lib\site-packages\django\db\models\sql\query.py", line 1318, in _add_q
    split_subq=split_subq, simple_col=simple_col,
  File "C:\Python37\lib\site-packages\django\db\models\sql\query.py", line 1251, in build_filter
    condition = self.build_lookup(lookups, col, value)
  File "C:\Python37\lib\site-packages\django\db\models\sql\query.py", line 1116, in build_lookup
    lookup = lookup_class(lhs, rhs)
  File "C:\Python37\lib\site-packages\django\db\models\lookups.py", line 20, in __init__
    self.rhs = self.get_prep_lookup()
  File "C:\Python37\lib\site-packages\django\db\models\lookups.py", line 70, in get_prep_lookup
    return self.lhs.output_field.get_prep_value(self.rhs)
  File "C:\Python37\lib\site-packages\django\db\models\fields\__init__.py", line 1821, in get_prep_value
    return int(value)
ValueError: invalid literal for int() with base 10: 'id'
WARNING:django.request:Not Found: /project_eval_form/events.js
DEBUG:root:got to submitProjectEval!!
DEBUG:root:form is valid
ERROR:django.request:Internal Server Error: /project_eval_form/submitted
Traceback (most recent call last):
  File "C:\Python37\lib\site-packages\django\core\handlers\exception.py", line 34, in inner
    response = get_response(request)
  File "C:\Python37\lib\site-packages\django\core\handlers\base.py", line 115, in _get_response
    response = self.process_exception_by_middleware(e, request)
  File "C:\Python37\lib\site-packages\django\core\handlers\base.py", line 113, in _get_response
    response = wrapped_callback(request, *callback_args, **callback_kwargs)
  File "E:\Documents\GitHub\Senior-Design-Scoring-System\Django\scoringsystem\scoringsystem\views.py", line 19, in submitProjectEvalView
    return submitProjectEval(request)
  File "C:\Python37\lib\site-packages\django\views\decorators\csrf.py", line 54, in wrapped_view
    return view_func(*args, **kwargs)
  File "E:\Documents\GitHub\Senior-Design-Scoring-System\Django\scoringsystem\scoringsystem\views.py", line 105, in submitProjectEval
    score.save()
  File "C:\Python37\lib\site-packages\django\db\models\base.py", line 741, in save
    force_update=force_update, update_fields=update_fields)
  File "C:\Python37\lib\site-packages\django\db\models\base.py", line 779, in save_base
    force_update, using, update_fields,
  File "C:\Python37\lib\site-packages\django\db\models\base.py", line 851, in _save_table
    forced_update)
  File "C:\Python37\lib\site-packages\django\db\models\base.py", line 880, in _do_update
    filtered = base_qs.filter(pk=pk_val)
  File "C:\Python37\lib\site-packages\django\db\models\query.py", line 892, in filter
    return self._filter_or_exclude(False, *args, **kwargs)
  File "C:\Python37\lib\site-packages\django\db\models\query.py", line 910, in _filter_or_exclude
    clone.query.add_q(Q(*args, **kwargs))
  File "C:\Python37\lib\site-packages\django\db\models\sql\query.py", line 1290, in add_q
    clause, _ = self._add_q(q_object, self.used_aliases)
  File "C:\Python37\lib\site-packages\django\db\models\sql\query.py", line 1318, in _add_q
    split_subq=split_subq, simple_col=simple_col,
  File "C:\Python37\lib\site-packages\django\db\models\sql\query.py", line 1251, in build_filter
    condition = self.build_lookup(lookups, col, value)
  File "C:\Python37\lib\site-packages\django\db\models\sql\query.py", line 1116, in build_lookup
    lookup = lookup_class(lhs, rhs)
  File "C:\Python37\lib\site-packages\django\db\models\lookups.py", line 20, in __init__
    self.rhs = self.get_prep_lookup()
  File "C:\Python37\lib\site-packages\django\db\models\lookups.py", line 70, in get_prep_lookup
    return self.lhs.output_field.get_prep_value(self.rhs)
  File "C:\Python37\lib\site-packages\django\db\models\fields\__init__.py", line 1821, in get_prep_value
    return int(value)
ValueError: invalid literal for int() with base 10: 'id'
DEBUG:root:got to submitProjectEval!!
DEBUG:root:form is valid
ERROR:django.request:Internal Server Error: /project_eval_form/submitted
Traceback (most recent call last):
  File "C:\Python37\lib\site-packages\django\db\backends\utils.py", line 84, in _execute
    return self.cursor.execute(sql, params)
psycopg2.errors.UndefinedTable: relation "scoringsystem_projecteval" does not exist
LINE 1: UPDATE "scoringsystem_projecteval" SET "judge_email" = 'emai...
               ^


The above exception was the direct cause of the following exception:

Traceback (most recent call last):
  File "C:\Python37\lib\site-packages\django\core\handlers\exception.py", line 34, in inner
    response = get_response(request)
  File "C:\Python37\lib\site-packages\django\core\handlers\base.py", line 115, in _get_response
    response = self.process_exception_by_middleware(e, request)
  File "C:\Python37\lib\site-packages\django\core\handlers\base.py", line 113, in _get_response
    response = wrapped_callback(request, *callback_args, **callback_kwargs)
  File "E:\Documents\GitHub\Senior-Design-Scoring-System\Django\scoringsystem\scoringsystem\views.py", line 19, in submitProjectEvalView
    return submitProjectEval(request)
  File "C:\Python37\lib\site-packages\django\views\decorators\csrf.py", line 54, in wrapped_view
    return view_func(*args, **kwargs)
  File "E:\Documents\GitHub\Senior-Design-Scoring-System\Django\scoringsystem\scoringsystem\views.py", line 105, in submitProjectEval
    score.save()
  File "C:\Python37\lib\site-packages\django\db\models\base.py", line 741, in save
    force_update=force_update, update_fields=update_fields)
  File "C:\Python37\lib\site-packages\django\db\models\base.py", line 779, in save_base
    force_update, using, update_fields,
  File "C:\Python37\lib\site-packages\django\db\models\base.py", line 851, in _save_table
    forced_update)
  File "C:\Python37\lib\site-packages\django\db\models\base.py", line 900, in _do_update
    return filtered._update(values) > 0
  File "C:\Python37\lib\site-packages\django\db\models\query.py", line 760, in _update
    return query.get_compiler(self.db).execute_sql(CURSOR)
  File "C:\Python37\lib\site-packages\django\db\models\sql\compiler.py", line 1429, in execute_sql
    cursor = super().execute_sql(result_type)
  File "C:\Python37\lib\site-packages\django\db\models\sql\compiler.py", line 1100, in execute_sql
    cursor.execute(sql, params)
  File "C:\Python37\lib\site-packages\django\db\backends\utils.py", line 99, in execute
    return super().execute(sql, params)
  File "C:\Python37\lib\site-packages\django\db\backends\utils.py", line 67, in execute
    return self._execute_with_wrappers(sql, params, many=False, executor=self._execute)
  File "C:\Python37\lib\site-packages\django\db\backends\utils.py", line 76, in _execute_with_wrappers
    return executor(sql, params, many, context)
  File "C:\Python37\lib\site-packages\django\db\backends\utils.py", line 84, in _execute
    return self.cursor.execute(sql, params)
  File "C:\Python37\lib\site-packages\django\db\utils.py", line 89, in __exit__
    raise dj_exc_value.with_traceback(traceback) from exc_value
  File "C:\Python37\lib\site-packages\django\db\backends\utils.py", line 84, in _execute
    return self.cursor.execute(sql, params)
django.db.utils.ProgrammingError: relation "scoringsystem_projecteval" does not exist
LINE 1: UPDATE "scoringsystem_projecteval" SET "judge_email" = 'emai...
               ^

WARNING:django.request:Not Found: /judge_eval_form
WARNING:django.request:Not Found: /judge_eval_form/
WARNING:django.request:Not Found: /projects_eval_form/
WARNING:django.request:Not Found: /js/functions.js
WARNING:django.request:Not Found: /project_eval_form/events.js
WARNING:django.request:Not Found: /project_eval_form/events.js
WARNING:django.request:Not Found: /js/functions.js
WARNING:django.request:Not Found: /project_eval_form/events.js
WARNING:django.request:Not Found: /project_eval_form/events.js
WARNING:django.request:Not Found: /js/functions.js
WARNING:django.request:Not Found: /project_eval_form/events.js
WARNING:django.request:Not Found: /js/functions.js
WARNING:django.request:Not Found: /project_eval_form/events.js
WARNING:django.request:Not Found: /js/functions.js
WARNING:django.request:Not Found: /project_eval_form/events.js
WARNING:django.request:Not Found: /project_eval_form/events.js
WARNING:django.request:Not Found: /js/functions.js
WARNING:django.request:Not Found: /project_eval_form/events.js
WARNING:django.request:Not Found: /js/functions.js
WARNING:django.request:Not Found: /project_eval_form/events.js
WARNING:django.request:Not Found: /js/functions.js
WARNING:django.request:Not Found: /project_eval_form/events.js
WARNING:django.request:Not Found: /js/functions.js
WARNING:django.request:Not Found: /project_eval_form/events.js
WARNING:django.request:Not Found: /js/functions.js
WARNING:django.request:Not Found: /project_eval_form/events.js
WARNING:django.request:Not Found: /judge-eval-form/
WARNING:django.request:Not Found: /judge-exp-eval-form/
WARNING:django.request:Not Found: /js/functions.js
WARNING:django.request:Not Found: /project_eval_form/events.js
WARNING:django.request:Not Found: /js/functions.js
WARNING:django.request:Not Found: /project_eval_form/events.js
WARNING:django.request:Not Found: /js/functions.js
WARNING:django.request:Not Found: /project_eval_form/events.js
WARNING:django.request:Not Found: /js/functions.js
WARNING:django.request:Not Found: /project_eval_form/events.js
WARNING:django.request:Not Found: /js/functions.js
WARNING:django.request:Not Found: /project_eval_form/events.js
WARNING:django.request:Not Found: /js/functions.js
WARNING:django.request:Not Found: /project_eval_form/events.js
DEBUG:root:inside createSessionView
DEBUG:root:inside submittedCreatedSessionView
DEBUG:root:got to submitCreatedSession!!
DEBUG:root:form is valid
WARNING:django.request:Not Found: /js/functions.js
WARNING:django.request:Not Found: /admin_home/events.js
INFO:django.utils.autoreload:E:\Documents\GitHub\Senior-Design-Scoring-System\Django\scoringsystem\scoringsystem\models.py changed, reloading.
DEBUG:root:inside createSessionView
DEBUG:root:inside submittedCreatedSessionView
DEBUG:root:got to submitCreatedSession!!
DEBUG:root:form is valid
ERROR:django.request:Internal Server Error: /admin_home/create_session_form/submitted
Traceback (most recent call last):
  File "C:\Python37\lib\site-packages\django\core\handlers\exception.py", line 34, in inner
    response = get_response(request)
  File "C:\Python37\lib\site-packages\django\core\handlers\base.py", line 115, in _get_response
    response = self.process_exception_by_middleware(e, request)
  File "C:\Python37\lib\site-packages\django\core\handlers\base.py", line 113, in _get_response
    response = wrapped_callback(request, *callback_args, **callback_kwargs)
  File "E:\Documents\GitHub\Senior-Design-Scoring-System\Django\scoringsystem\scoringsystem\views.py", line 28, in submittedCreatedSessionView
    return submitCreatedSession(request)
  File "E:\Documents\GitHub\Senior-Design-Scoring-System\Django\scoringsystem\scoringsystem\views.py", line 84, in submitCreatedSession
    return render(request, '/admin_home/')
  File "C:\Python37\lib\site-packages\django\shortcuts.py", line 36, in render
    content = loader.render_to_string(template_name, context, request, using=using)
  File "C:\Python37\lib\site-packages\django\template\loader.py", line 61, in render_to_string
    template = get_template(template_name, using=using)
  File "C:\Python37\lib\site-packages\django\template\loader.py", line 19, in get_template
    raise TemplateDoesNotExist(template_name, chain=chain)
django.template.exceptions.TemplateDoesNotExist: /admin_home/
DEBUG:root:inside submittedCreatedSessionView
DEBUG:root:got to submitCreatedSession!!
DEBUG:root:form is valid
ERROR:django.request:Internal Server Error: /admin_home/create_session_form/submitted
Traceback (most recent call last):
  File "C:\Python37\lib\site-packages\django\core\handlers\exception.py", line 34, in inner
    response = get_response(request)
  File "C:\Python37\lib\site-packages\django\core\handlers\base.py", line 115, in _get_response
    response = self.process_exception_by_middleware(e, request)
  File "C:\Python37\lib\site-packages\django\core\handlers\base.py", line 113, in _get_response
    response = wrapped_callback(request, *callback_args, **callback_kwargs)
  File "E:\Documents\GitHub\Senior-Design-Scoring-System\Django\scoringsystem\scoringsystem\views.py", line 28, in submittedCreatedSessionView
    return submitCreatedSession(request)
  File "E:\Documents\GitHub\Senior-Design-Scoring-System\Django\scoringsystem\scoringsystem\views.py", line 84, in submitCreatedSession
    return render(request, '/admin_home/')
  File "C:\Python37\lib\site-packages\django\shortcuts.py", line 36, in render
    content = loader.render_to_string(template_name, context, request, using=using)
  File "C:\Python37\lib\site-packages\django\template\loader.py", line 61, in render_to_string
    template = get_template(template_name, using=using)
  File "C:\Python37\lib\site-packages\django\template\loader.py", line 19, in get_template
    raise TemplateDoesNotExist(template_name, chain=chain)
django.template.exceptions.TemplateDoesNotExist: /admin_home/
INFO:django.utils.autoreload:E:\Documents\GitHub\Senior-Design-Scoring-System\Django\scoringsystem\scoringsystem\views.py changed, reloading.
DEBUG:root:inside createSessionView
DEBUG:root:inside submittedCreatedSessionView
DEBUG:root:got to submitCreatedSession!!
DEBUG:root:form is valid
ERROR:django.request:Internal Server Error: /admin_home/create_session_form/submitted
Traceback (most recent call last):
  File "C:\Python37\lib\site-packages\django\core\handlers\exception.py", line 34, in inner
    response = get_response(request)
  File "C:\Python37\lib\site-packages\django\core\handlers\base.py", line 115, in _get_response
    response = self.process_exception_by_middleware(e, request)
  File "C:\Python37\lib\site-packages\django\core\handlers\base.py", line 113, in _get_response
    response = wrapped_callback(request, *callback_args, **callback_kwargs)
  File "E:\Documents\GitHub\Senior-Design-Scoring-System\Django\scoringsystem\scoringsystem\views.py", line 28, in submittedCreatedSessionView
    return submitCreatedSession(request)
  File "E:\Documents\GitHub\Senior-Design-Scoring-System\Django\scoringsystem\scoringsystem\views.py", line 84, in submitCreatedSession
    return render(request, '/admin_home/')
  File "C:\Python37\lib\site-packages\django\shortcuts.py", line 36, in render
    content = loader.render_to_string(template_name, context, request, using=using)
  File "C:\Python37\lib\site-packages\django\template\loader.py", line 61, in render_to_string
    template = get_template(template_name, using=using)
  File "C:\Python37\lib\site-packages\django\template\loader.py", line 19, in get_template
    raise TemplateDoesNotExist(template_name, chain=chain)
django.template.exceptions.TemplateDoesNotExist: /admin_home/
DEBUG:root:inside submittedCreatedSessionView
DEBUG:root:got to submitCreatedSession!!
DEBUG:root:form is valid
ERROR:django.request:Internal Server Error: /admin_home/create_session_form/submitted
Traceback (most recent call last):
  File "C:\Python37\lib\site-packages\django\core\handlers\exception.py", line 34, in inner
    response = get_response(request)
  File "C:\Python37\lib\site-packages\django\core\handlers\base.py", line 115, in _get_response
    response = self.process_exception_by_middleware(e, request)
  File "C:\Python37\lib\site-packages\django\core\handlers\base.py", line 113, in _get_response
    response = wrapped_callback(request, *callback_args, **callback_kwargs)
  File "E:\Documents\GitHub\Senior-Design-Scoring-System\Django\scoringsystem\scoringsystem\views.py", line 28, in submittedCreatedSessionView
    return submitCreatedSession(request)
  File "E:\Documents\GitHub\Senior-Design-Scoring-System\Django\scoringsystem\scoringsystem\views.py", line 84, in submitCreatedSession
    return render(request, '/admin_home/')
  File "C:\Python37\lib\site-packages\django\shortcuts.py", line 36, in render
    content = loader.render_to_string(template_name, context, request, using=using)
  File "C:\Python37\lib\site-packages\django\template\loader.py", line 61, in render_to_string
    template = get_template(template_name, using=using)
  File "C:\Python37\lib\site-packages\django\template\loader.py", line 19, in get_template
    raise TemplateDoesNotExist(template_name, chain=chain)
django.template.exceptions.TemplateDoesNotExist: /admin_home/
DEBUG:root:inside submittedCreatedSessionView
DEBUG:root:got to submitCreatedSession!!
DEBUG:root:form is valid
ERROR:django.request:Internal Server Error: /admin_home/create_session_form/submitted
Traceback (most recent call last):
  File "C:\Python37\lib\site-packages\django\core\handlers\exception.py", line 34, in inner
    response = get_response(request)
  File "C:\Python37\lib\site-packages\django\core\handlers\base.py", line 115, in _get_response
    response = self.process_exception_by_middleware(e, request)
  File "C:\Python37\lib\site-packages\django\core\handlers\base.py", line 113, in _get_response
    response = wrapped_callback(request, *callback_args, **callback_kwargs)
  File "E:\Documents\GitHub\Senior-Design-Scoring-System\Django\scoringsystem\scoringsystem\views.py", line 28, in submittedCreatedSessionView
    return submitCreatedSession(request)
  File "E:\Documents\GitHub\Senior-Design-Scoring-System\Django\scoringsystem\scoringsystem\views.py", line 84, in submitCreatedSession
    return render(request, '/admin_home/')
  File "C:\Python37\lib\site-packages\django\shortcuts.py", line 36, in render
    content = loader.render_to_string(template_name, context, request, using=using)
  File "C:\Python37\lib\site-packages\django\template\loader.py", line 61, in render_to_string
    template = get_template(template_name, using=using)
  File "C:\Python37\lib\site-packages\django\template\loader.py", line 19, in get_template
    raise TemplateDoesNotExist(template_name, chain=chain)
django.template.exceptions.TemplateDoesNotExist: /admin_home/
WARNING:django.request:Not Found: /js/functions.js
WARNING:django.request:Not Found: /admin_home/events.js
INFO:django.utils.autoreload:E:\Documents\GitHub\Senior-Design-Scoring-System\Django\scoringsystem\scoringsystem\urls.py changed, reloading.
DEBUG:root:inside createSessionView
DEBUG:root:inside submittedCreatedSessionView
DEBUG:root:got to submitCreatedSession!!
DEBUG:root:form is valid
ERROR:django.request:Internal Server Error: /admin_home/create_session_form/submitted
Traceback (most recent call last):
  File "C:\Python37\lib\site-packages\django\core\handlers\exception.py", line 34, in inner
    response = get_response(request)
  File "C:\Python37\lib\site-packages\django\core\handlers\base.py", line 115, in _get_response
    response = self.process_exception_by_middleware(e, request)
  File "C:\Python37\lib\site-packages\django\core\handlers\base.py", line 113, in _get_response
    response = wrapped_callback(request, *callback_args, **callback_kwargs)
  File "E:\Documents\GitHub\Senior-Design-Scoring-System\Django\scoringsystem\scoringsystem\views.py", line 28, in submittedCreatedSessionView
    return submitCreatedSession(request)
  File "E:\Documents\GitHub\Senior-Design-Scoring-System\Django\scoringsystem\scoringsystem\views.py", line 84, in submitCreatedSession
    return render(request, '/admin_home/')
  File "C:\Python37\lib\site-packages\django\shortcuts.py", line 36, in render
    content = loader.render_to_string(template_name, context, request, using=using)
  File "C:\Python37\lib\site-packages\django\template\loader.py", line 61, in render_to_string
    template = get_template(template_name, using=using)
  File "C:\Python37\lib\site-packages\django\template\loader.py", line 19, in get_template
    raise TemplateDoesNotExist(template_name, chain=chain)
django.template.exceptions.TemplateDoesNotExist: /admin_home/
INFO:django.utils.autoreload:E:\Documents\GitHub\Senior-Design-Scoring-System\Django\scoringsystem\scoringsystem\views.py changed, reloading.
DEBUG:root:inside submittedCreatedSessionView
DEBUG:root:got to submitCreatedSession!!
DEBUG:root:form is valid
WARNING:django.request:Not Found: /admin_home/js/functions.js
WARNING:django.request:Not Found: /admin_home/create_session_form/events.js
INFO:django.utils.autoreload:E:\Documents\GitHub\Senior-Design-Scoring-System\Django\scoringsystem\scoringsystem\views.py changed, reloading.
DEBUG:root:inside submittedAssignJudgesView
DEBUG:root:got to submitAndAddJudge!!
DEBUG:root:form is valid
ERROR:django.request:Internal Server Error: /admin_home/add_judges_form/submitted
Traceback (most recent call last):
  File "C:\Python37\lib\site-packages\django\db\backends\utils.py", line 84, in _execute
    return self.cursor.execute(sql, params)
psycopg2.errors.UndefinedTable: relation "scoringsystem_judge" does not exist
LINE 1: UPDATE "scoringsystem_judge" SET "judge_email" = 'email', "s...
               ^


The above exception was the direct cause of the following exception:

Traceback (most recent call last):
  File "C:\Python37\lib\site-packages\django\core\handlers\exception.py", line 34, in inner
    response = get_response(request)
  File "C:\Python37\lib\site-packages\django\core\handlers\base.py", line 115, in _get_response
    response = self.process_exception_by_middleware(e, request)
  File "C:\Python37\lib\site-packages\django\core\handlers\base.py", line 113, in _get_response
    response = wrapped_callback(request, *callback_args, **callback_kwargs)
  File "E:\Documents\GitHub\Senior-Design-Scoring-System\Django\scoringsystem\scoringsystem\views.py", line 52, in submittedAssignJudgesView
    return submitAndAddJudge(request)
  File "E:\Documents\GitHub\Senior-Design-Scoring-System\Django\scoringsystem\scoringsystem\views.py", line 69, in submitAndAddJudge
    judge.save()
  File "C:\Python37\lib\site-packages\django\db\models\base.py", line 741, in save
    force_update=force_update, update_fields=update_fields)
  File "C:\Python37\lib\site-packages\django\db\models\base.py", line 779, in save_base
    force_update, using, update_fields,
  File "C:\Python37\lib\site-packages\django\db\models\base.py", line 851, in _save_table
    forced_update)
  File "C:\Python37\lib\site-packages\django\db\models\base.py", line 900, in _do_update
    return filtered._update(values) > 0
  File "C:\Python37\lib\site-packages\django\db\models\query.py", line 760, in _update
    return query.get_compiler(self.db).execute_sql(CURSOR)
  File "C:\Python37\lib\site-packages\django\db\models\sql\compiler.py", line 1429, in execute_sql
    cursor = super().execute_sql(result_type)
  File "C:\Python37\lib\site-packages\django\db\models\sql\compiler.py", line 1100, in execute_sql
    cursor.execute(sql, params)
  File "C:\Python37\lib\site-packages\django\db\backends\utils.py", line 99, in execute
    return super().execute(sql, params)
  File "C:\Python37\lib\site-packages\django\db\backends\utils.py", line 67, in execute
    return self._execute_with_wrappers(sql, params, many=False, executor=self._execute)
  File "C:\Python37\lib\site-packages\django\db\backends\utils.py", line 76, in _execute_with_wrappers
    return executor(sql, params, many, context)
  File "C:\Python37\lib\site-packages\django\db\backends\utils.py", line 84, in _execute
    return self.cursor.execute(sql, params)
  File "C:\Python37\lib\site-packages\django\db\utils.py", line 89, in __exit__
    raise dj_exc_value.with_traceback(traceback) from exc_value
  File "C:\Python37\lib\site-packages\django\db\backends\utils.py", line 84, in _execute
    return self.cursor.execute(sql, params)
django.db.utils.ProgrammingError: relation "scoringsystem_judge" does not exist
LINE 1: UPDATE "scoringsystem_judge" SET "judge_email" = 'email', "s...
               ^

DEBUG:root:inside submittedAssignJudgesView
DEBUG:root:got to submitAndAddJudge!!
DEBUG:root:form is valid
ERROR:django.request:Internal Server Error: /admin_home/add_judges_form/submitted
Traceback (most recent call last):
  File "C:\Python37\lib\site-packages\django\db\backends\utils.py", line 84, in _execute
    return self.cursor.execute(sql, params)
psycopg2.errors.ForeignKeyViolation: insert or update on table "scoringsystem_judge" violates foreign key constraint "scoringsystem_judge_session_id_fkey"
DETAIL:  Key (session_id)=(0) is not present in table "scoringsystem_session".


The above exception was the direct cause of the following exception:

Traceback (most recent call last):
  File "C:\Python37\lib\site-packages\django\core\handlers\exception.py", line 34, in inner
    response = get_response(request)
  File "C:\Python37\lib\site-packages\django\core\handlers\base.py", line 115, in _get_response
    response = self.process_exception_by_middleware(e, request)
  File "C:\Python37\lib\site-packages\django\core\handlers\base.py", line 113, in _get_response
    response = wrapped_callback(request, *callback_args, **callback_kwargs)
  File "E:\Documents\GitHub\Senior-Design-Scoring-System\Django\scoringsystem\scoringsystem\views.py", line 52, in submittedAssignJudgesView
    return submitAndAddJudge(request)
  File "E:\Documents\GitHub\Senior-Design-Scoring-System\Django\scoringsystem\scoringsystem\views.py", line 69, in submitAndAddJudge
    judge.save()
  File "C:\Python37\lib\site-packages\django\db\models\base.py", line 741, in save
    force_update=force_update, update_fields=update_fields)
  File "C:\Python37\lib\site-packages\django\db\models\base.py", line 779, in save_base
    force_update, using, update_fields,
  File "C:\Python37\lib\site-packages\django\db\models\base.py", line 870, in _save_table
    result = self._do_insert(cls._base_manager, using, fields, update_pk, raw)
  File "C:\Python37\lib\site-packages\django\db\models\base.py", line 908, in _do_insert
    using=using, raw=raw)
  File "C:\Python37\lib\site-packages\django\db\models\manager.py", line 82, in manager_method
    return getattr(self.get_queryset(), name)(*args, **kwargs)
  File "C:\Python37\lib\site-packages\django\db\models\query.py", line 1186, in _insert
    return query.get_compiler(using=using).execute_sql(return_id)
  File "C:\Python37\lib\site-packages\django\db\models\sql\compiler.py", line 1335, in execute_sql
    cursor.execute(sql, params)
  File "C:\Python37\lib\site-packages\django\db\backends\utils.py", line 99, in execute
    return super().execute(sql, params)
  File "C:\Python37\lib\site-packages\django\db\backends\utils.py", line 67, in execute
    return self._execute_with_wrappers(sql, params, many=False, executor=self._execute)
  File "C:\Python37\lib\site-packages\django\db\backends\utils.py", line 76, in _execute_with_wrappers
    return executor(sql, params, many, context)
  File "C:\Python37\lib\site-packages\django\db\backends\utils.py", line 84, in _execute
    return self.cursor.execute(sql, params)
  File "C:\Python37\lib\site-packages\django\db\utils.py", line 89, in __exit__
    raise dj_exc_value.with_traceback(traceback) from exc_value
  File "C:\Python37\lib\site-packages\django\db\backends\utils.py", line 84, in _execute
    return self.cursor.execute(sql, params)
django.db.utils.IntegrityError: insert or update on table "scoringsystem_judge" violates foreign key constraint "scoringsystem_judge_session_id_fkey"
DETAIL:  Key (session_id)=(0) is not present in table "scoringsystem_session".

WARNING:django.request:Not Found: /js/functions.js
WARNING:django.request:Not Found: /admin_home/events.js
DEBUG:root:inside createSessionView
DEBUG:root:inside submittedCreatedSessionView
DEBUG:root:got to submitCreatedSession!!
DEBUG:root:form is valid
WARNING:django.request:Not Found: /admin_home/js/functions.js
WARNING:django.request:Not Found: /admin_home/create_session_form/events.js
DEBUG:root:inside submittedCreatedSessionView
DEBUG:root:got to submitCreatedSession!!
DEBUG:root:form is valid
WARNING:django.request:Not Found: /admin_home/js/functions.js
WARNING:django.request:Not Found: /admin_home/create_session_form/events.js
DEBUG:root:inside submittedCreatedSessionView
DEBUG:root:got to submitCreatedSession!!
DEBUG:root:form is valid
WARNING:django.request:Not Found: /admin_home/js/functions.js
WARNING:django.request:Not Found: /admin_home/create_session_form/events.js
INFO:django.utils.autoreload:E:\Documents\GitHub\Senior-Design-Scoring-System\Django\scoringsystem\scoringsystem\views.py changed, reloading.
DEBUG:root:inside submittedCreatedSessionView
DEBUG:root:got to submitCreatedSession!!
DEBUG:root:form is valid
WARNING:django.request:Not Found: /admin_home/js/functions.js
WARNING:django.request:Not Found: /admin_home/create_session_form/events.js
WARNING:django.request:Not Found: /admin_home/create_session_form/create_session_form
INFO:django.utils.autoreload:E:\Documents\GitHub\Senior-Design-Scoring-System\Django\scoringsystem\scoringsystem\views.py changed, reloading.
DEBUG:root:inside createSessionView
DEBUG:root:inside submittedCreatedSessionView
DEBUG:root:got to submitCreatedSession!!
DEBUG:root:form is valid
WARNING:django.request:Not Found: /admin_home/js/functions.js
WARNING:django.request:Not Found: /admin_home/create_session_form/events.js
WARNING:django.request:Not Found: /admin_home/create_session_form/events.js
INFO:django.utils.autoreload:E:\Documents\GitHub\Senior-Design-Scoring-System\Django\scoringsystem\scoringsystem\views.py changed, reloading.
DEBUG:root:inside submittedCreatedSessionView
DEBUG:root:got to submitCreatedSession!!
DEBUG:root:method is not POST
WARNING:django.request:Not Found: /admin_home/create_session_form/index.html
WARNING:django.request:Not Found: /js/functions.js
WARNING:django.request:Not Found: /admin_home/events.js
DEBUG:root:inside createSessionView
DEBUG:root:inside submittedCreatedSessionView
DEBUG:root:got to submitCreatedSession!!
DEBUG:root:form is valid
WARNING:django.request:Not Found: /admin_home/js/functions.js
WARNING:django.request:Not Found: /admin_home/create_session_form/events.js
INFO:django.utils.autoreload:E:\Documents\GitHub\Senior-Design-Scoring-System\Django\scoringsystem\scoringsystem\views.py changed, reloading.
DEBUG:root:inside createSessionView
DEBUG:root:inside submittedCreatedSessionView
DEBUG:root:got to submitCreatedSession!!
DEBUG:root:form is valid
WARNING:django.request:Not Found: /js/functions.js
WARNING:django.request:Not Found: /admin_home/events.js
DEBUG:root:inside createSessionView
DEBUG:root:inside submittedCreatedSessionView
DEBUG:root:got to submitCreatedSession!!
DEBUG:root:form is valid
WARNING:django.request:Not Found: /js/functions.js
WARNING:django.request:Not Found: /admin_home/events.js
DEBUG:root:inside createSessionView
DEBUG:root:inside submittedCreatedSessionView
DEBUG:root:got to submitCreatedSession!!
DEBUG:root:form is valid
WARNING:django.request:Not Found: /js/functions.js
WARNING:django.request:Not Found: /admin_home/events.js
DEBUG:root:inside createSessionView
DEBUG:root:inside submittedCreatedSessionView
DEBUG:root:got to submitCreatedSession!!
DEBUG:root:form is valid
WARNING:django.request:Not Found: /js/functions.js
WARNING:django.request:Not Found: /admin_home/events.js
WARNING:django.request:Not Found: /js/functions.js
WARNING:django.request:Not Found: /admin_home/events.js
WARNING:django.request:Not Found: /js/functions.js
WARNING:django.request:Not Found: /admin_home/events.js
INFO:django.utils.autoreload:E:\Documents\GitHub\Senior-Design-Scoring-System\Django\scoringsystem\scoringsystem\models.py changed, reloading.
DEBUG:root:inside createProjectForm
DEBUG:root:inside submittedCreatedProjectForm
DEBUG:root:got to submitCreatedProject!!
DEBUG:root:form is valid
ERROR:django.request:Internal Server Error: /admin_home/create_project_form/submitted
Traceback (most recent call last):
  File "C:\Python37\lib\site-packages\django\db\backends\utils.py", line 84, in _execute
    return self.cursor.execute(sql, params)
psycopg2.errors.UndefinedTable: relation "scoringsystem_project" does not exist
LINE 1: INSERT INTO "scoringsystem_project" ("session_id", "project_...
                    ^


The above exception was the direct cause of the following exception:

Traceback (most recent call last):
  File "C:\Python37\lib\site-packages\django\core\handlers\exception.py", line 34, in inner
    response = get_response(request)
  File "C:\Python37\lib\site-packages\django\core\handlers\base.py", line 115, in _get_response
    response = self.process_exception_by_middleware(e, request)
  File "C:\Python37\lib\site-packages\django\core\handlers\base.py", line 113, in _get_response
    response = wrapped_callback(request, *callback_args, **callback_kwargs)
  File "E:\Documents\GitHub\Senior-Design-Scoring-System\Django\scoringsystem\scoringsystem\views.py", line 40, in submittedCreatedProjectForm
    return submitCreatedProject(request)
  File "E:\Documents\GitHub\Senior-Design-Scoring-System\Django\scoringsystem\scoringsystem\views.py", line 131, in submitCreatedProject
    project.save()
  File "C:\Python37\lib\site-packages\django\db\models\base.py", line 741, in save
    force_update=force_update, update_fields=update_fields)
  File "C:\Python37\lib\site-packages\django\db\models\base.py", line 779, in save_base
    force_update, using, update_fields,
  File "C:\Python37\lib\site-packages\django\db\models\base.py", line 870, in _save_table
    result = self._do_insert(cls._base_manager, using, fields, update_pk, raw)
  File "C:\Python37\lib\site-packages\django\db\models\base.py", line 908, in _do_insert
    using=using, raw=raw)
  File "C:\Python37\lib\site-packages\django\db\models\manager.py", line 82, in manager_method
    return getattr(self.get_queryset(), name)(*args, **kwargs)
  File "C:\Python37\lib\site-packages\django\db\models\query.py", line 1186, in _insert
    return query.get_compiler(using=using).execute_sql(return_id)
  File "C:\Python37\lib\site-packages\django\db\models\sql\compiler.py", line 1335, in execute_sql
    cursor.execute(sql, params)
  File "C:\Python37\lib\site-packages\django\db\backends\utils.py", line 99, in execute
    return super().execute(sql, params)
  File "C:\Python37\lib\site-packages\django\db\backends\utils.py", line 67, in execute
    return self._execute_with_wrappers(sql, params, many=False, executor=self._execute)
  File "C:\Python37\lib\site-packages\django\db\backends\utils.py", line 76, in _execute_with_wrappers
    return executor(sql, params, many, context)
  File "C:\Python37\lib\site-packages\django\db\backends\utils.py", line 84, in _execute
    return self.cursor.execute(sql, params)
  File "C:\Python37\lib\site-packages\django\db\utils.py", line 89, in __exit__
    raise dj_exc_value.with_traceback(traceback) from exc_value
  File "C:\Python37\lib\site-packages\django\db\backends\utils.py", line 84, in _execute
    return self.cursor.execute(sql, params)
django.db.utils.ProgrammingError: relation "scoringsystem_project" does not exist
LINE 1: INSERT INTO "scoringsystem_project" ("session_id", "project_...
                    ^

WARNING:django.request:Not Found: /js/functions.js
WARNING:django.request:Not Found: /admin_home/events.js
DEBUG:root:inside createProjectForm
DEBUG:root:inside submittedCreatedProjectForm
DEBUG:root:got to submitCreatedProject!!
DEBUG:root:form is valid
WARNING:django.request:Not Found: /js/functions.js
WARNING:django.request:Not Found: /admin_home/events.js
WARNING:django.request:Not Found: /js/functions.js
WARNING:django.request:Not Found: /admin_home/events.js
DEBUG:root:inside createProjectForm
WARNING:django.request:Not Found: /admin_home/events.js
WARNING:django.request:Not Found: /js/functions.js
WARNING:django.request:Not Found: /admin_home/events.js
ERROR:django.request:Internal Server Error: /admin_home/delete_session
Traceback (most recent call last):
  File "C:\Python37\lib\site-packages\django\core\handlers\exception.py", line 34, in inner
    response = get_response(request)
  File "C:\Python37\lib\site-packages\django\core\handlers\base.py", line 115, in _get_response
    response = self.process_exception_by_middleware(e, request)
  File "C:\Python37\lib\site-packages\django\core\handlers\base.py", line 113, in _get_response
    response = wrapped_callback(request, *callback_args, **callback_kwargs)
  File "E:\Documents\GitHub\Senior-Design-Scoring-System\Django\scoringsystem\scoringsystem\views.py", line 62, in deleteSessionView
    projects = m.project.objects.filter(assigned_session_id=session_id)
  File "C:\Python37\lib\site-packages\django\db\models\manager.py", line 82, in manager_method
    return getattr(self.get_queryset(), name)(*args, **kwargs)
  File "C:\Python37\lib\site-packages\django\db\models\query.py", line 892, in filter
    return self._filter_or_exclude(False, *args, **kwargs)
  File "C:\Python37\lib\site-packages\django\db\models\query.py", line 910, in _filter_or_exclude
    clone.query.add_q(Q(*args, **kwargs))
  File "C:\Python37\lib\site-packages\django\db\models\sql\query.py", line 1290, in add_q
    clause, _ = self._add_q(q_object, self.used_aliases)
  File "C:\Python37\lib\site-packages\django\db\models\sql\query.py", line 1318, in _add_q
    split_subq=split_subq, simple_col=simple_col,
  File "C:\Python37\lib\site-packages\django\db\models\sql\query.py", line 1190, in build_filter
    lookups, parts, reffed_expression = self.solve_lookup_type(arg)
  File "C:\Python37\lib\site-packages\django\db\models\sql\query.py", line 1049, in solve_lookup_type
    _, field, _, lookup_parts = self.names_to_path(lookup_splitted, self.get_meta())
  File "C:\Python37\lib\site-packages\django\db\models\sql\query.py", line 1420, in names_to_path
    "Choices are: %s" % (name, ", ".join(available)))
django.core.exceptions.FieldError: Cannot resolve keyword 'assigned_session_id' into field. Choices are: average_score, group_members, id, project_desc, project_name, session_id
INFO:django.utils.autoreload:E:\Documents\GitHub\Senior-Design-Scoring-System\Django\scoringsystem\scoringsystem\views.py changed, reloading.
DEBUG:root:inside createSessionView
DEBUG:root:inside submittedCreatedSessionView
DEBUG:root:got to submitCreatedSession!!
DEBUG:root:form is valid
WARNING:django.request:Not Found: /js/functions.js
WARNING:django.request:Not Found: /admin_home/events.js
DEBUG:root:inside createProjectForm
INFO:django.utils.autoreload:E:\Documents\GitHub\Senior-Design-Scoring-System\Django\scoringsystem\scoringsystem\views.py changed, reloading.
DEBUG:root:inside createProjectForm
DEBUG:root:inside submittedCreatedProjectForm
DEBUG:root:got to submitCreatedProject!!
DEBUG:root:form is valid
WARNING:django.request:Not Found: /js/functions.js
WARNING:django.request:Not Found: /admin_home/events.js
WARNING:django.request:Not Found: /js/functions.js
WARNING:django.request:Not Found: /admin_home/events.js
DEBUG:root:inside createProjectForm
WARNING:django.request:Not Found: /admin_home/events.js
WARNING:django.request:Not Found: /js/functions.js
WARNING:django.request:Not Found: /admin_home/events.js
DEBUG:root:inside createProjectForm
WARNING:django.request:Not Found: /js/functions.js
WARNING:django.request:Not Found: /admin_home/events.js
DEBUG:root:inside createProjectForm
WARNING:django.request:Not Found: /js/functions.js
WARNING:django.request:Not Found: /admin_home/events.js
DEBUG:root:inside createProjectForm
DEBUG:root:inside createProjectForm
WARNING:django.request:Not Found: /admin_home/add_judges_form/submitted
WARNING:django.request:Not Found: /admin_home/add_judges_form/submitted
WARNING:django.request:Not Found: /js/functions.js
WARNING:django.request:Not Found: /admin_home/events.js
DEBUG:root:inside submittedAssignJudgesView
DEBUG:root:got to submitAndAddJudge!!
DEBUG:root:form is valid
WARNING:django.request:Not Found: /admin_home/events.js
WARNING:django.request:Not Found: /js/functions.js
WARNING:django.request:Not Found: /admin_home/events.js
DEBUG:root:inside submittedAssignJudgesView
DEBUG:root:got to submitAndAddJudge!!
DEBUG:root:form is valid
WARNING:django.request:Not Found: /js/functions.js
WARNING:django.request:Not Found: /admin_home/events.js
WARNING:django.request:Not Found: /js/functions.js
WARNING:django.request:Not Found: /admin_home/events.js
WARNING:django.request:Not Found: /js/functions.js
WARNING:django.request:Not Found: /admin_home/events.js
DEBUG:root:inside createProjectForm
DEBUG:root:inside createProjectForm
DEBUG:root:inside createProjectForm
DEBUG:root:inside submittedCreatedProjectForm
DEBUG:root:got to submitCreatedProject!!
DEBUG:root:form is valid
WARNING:django.request:Not Found: /js/functions.js
WARNING:django.request:Not Found: /admin_home/events.js
DEBUG:root:inside createProjectForm
WARNING:django.request:Not Found: /admin_home/events.js
WARNING:django.request:Not Found: /js/functions.js
WARNING:django.request:Not Found: /admin_home/events.js
DEBUG:root:inside createProjectForm
WARNING:django.request:Not Found: /admin_home/events.js
WARNING:django.request:Not Found: /js/functions.js
WARNING:django.request:Not Found: /admin_home/events.js
WARNING:django.request:Not Found: /js/functions.js
WARNING:django.request:Not Found: /admin_home/events.js
WARNING:django.request:Not Found: /js/functions.js
WARNING:django.request:Not Found: /admin_home/events.js
INFO:django.utils.autoreload:E:\Documents\GitHub\Senior-Design-Scoring-System\Django\scoringsystem\scoringsystem\settings.py changed, reloading.
DEBUG:root:inside createSessionView
DEBUG:root:inside submittedCreatedSessionView
DEBUG:root:got to submitCreatedSession!!
DEBUG:root:form is valid
WARNING:django.request:Not Found: /admin_home/events.js
WARNING:django.request:Not Found: /js/functions.js
WARNING:django.request:Not Found: /admin_home/events.js
WARNING:django.request:Not Found: /admin_home/events.js
WARNING:django.request:Not Found: /js/functions.js
WARNING:django.request:Not Found: /admin_home/events.js
WARNING:django.request:Not Found: /favicon.ico
WARNING:django.request:Not Found: /js/functions.js
WARNING:django.request:Not Found: /admin_home/events.js
WARNING:django.request:Not Found: /admin_home/events.js
DEBUG:root:inside createSessionView
DEBUG:root:inside submittedCreatedSessionView
DEBUG:root:got to submitCreatedSession!!
DEBUG:root:form is valid
WARNING:django.request:Not Found: /js/functions.js
WARNING:django.request:Not Found: /admin_home/events.js
WARNING:django.request:Not Found: /admin_home/events.js
DEBUG:root:inside createProjectForm
WARNING:django.request:Not Found: /js/functions.js
WARNING:django.request:Not Found: /admin_home/events.js
WARNING:django.request:Not Found: /js/functions.js
WARNING:django.request:Not Found: /admin_home/events.js
WARNING:django.request:Not Found: /favicon.ico
DEBUG:root:inside submittedCreatedProjectForm
DEBUG:root:got to submitCreatedProject!!
DEBUG:root:form is valid
WARNING:django.request:Not Found: /js/functions.js
WARNING:django.request:Not Found: /admin_home/events.js
WARNING:django.request:Not Found: /admin_home/events.js
DEBUG:root:inside submittedAssignJudgesView
DEBUG:root:got to submitAndAddJudge!!
DEBUG:root:form is valid
WARNING:django.request:Not Found: /admin_home/events.js
WARNING:django.request:Not Found: /js/functions.js
WARNING:django.request:Not Found: /admin_home/events.js
DEBUG:root:inside submittedAssignJudgesView
DEBUG:root:got to submitAndAddJudge!!
DEBUG:root:form is valid
WARNING:django.request:Not Found: /js/functions.js
WARNING:django.request:Not Found: /admin_home/events.js
DEBUG:root:inside createProjectForm
INFO:django.utils.autoreload:E:\Documents\GitHub\Senior-Design-Scoring-System\Django\scoringsystem\scoringsystem\settings.py changed, reloading.
DEBUG:root:inside submittedCreatedProjectForm
DEBUG:root:got to submitCreatedProject!!
DEBUG:root:form is valid
WARNING:django.request:Not Found: /js/functions.js
WARNING:django.request:Not Found: /admin_home/events.js
WARNING:django.request:Not Found: /admin_home/view_session_scores
DEBUG:root:inside createProjectForm
WARNING:django.request:Not Found: /admin_home/events.js
WARNING:django.request:Not Found: /js/functions.js
WARNING:django.request:Not Found: /admin_home/events.js
WARNING:django.request:Not Found: /js/functions.js
WARNING:django.request:Not Found: /admin_home/events.js
WARNING:django.request:Not Found: /admin
WARNING:django.request:Not Found: /admin
